WARNING 2019-12-13 08:04:00,838 base 93 Not Found: /
WARNING 2019-12-13 08:04:00,843 base 93 Not Found: /
WARNING 2019-12-13 08:04:00,844 basehttp 124 "GET / HTTP/1.1" 404 2033
WARNING 2019-12-13 08:04:00,846 basehttp 124 "GET / HTTP/1.1" 404 2033
WARNING 2019-12-13 08:04:05,245 base 93 Not Found: /admin/api/user/add/
WARNING 2019-12-13 08:04:05,246 basehttp 124 "GET /admin/api/user/add/ HTTP/1.1" 404 5227
WARNING 2019-12-13 08:04:05,716 base 93 Not Found: /favicon.ico
WARNING 2019-12-13 08:04:05,716 basehttp 124 "GET /favicon.ico HTTP/1.1" 404 2084
WARNING 2019-12-13 08:04:08,074 base 93 Not Found: /admin/api/
WARNING 2019-12-13 08:04:08,074 basehttp 124 "GET /admin/api/ HTTP/1.1" 404 5200
ERROR 2019-12-13 08:12:59,635 exception 118 Internal Server Error: /admin/fiction/author/
Traceback (most recent call last):
  File "G:\virtualenvs\luffy\lib\site-packages\django\db\backends\utils.py", line 85, in _execute
    return self.cursor.execute(sql, params)
  File "G:\virtualenvs\luffy\lib\site-packages\django\db\backends\mysql\base.py", line 71, in execute
    return self.cursor.execute(query, args)
  File "G:\virtualenvs\luffy\lib\site-packages\pymysql\cursors.py", line 170, in execute
    result = self._query(query)
  File "G:\virtualenvs\luffy\lib\site-packages\pymysql\cursors.py", line 328, in _query
    conn.query(q)
  File "G:\virtualenvs\luffy\lib\site-packages\pymysql\connections.py", line 517, in query
    self._affected_rows = self._read_query_result(unbuffered=unbuffered)
  File "G:\virtualenvs\luffy\lib\site-packages\pymysql\connections.py", line 732, in _read_query_result
    result.read()
  File "G:\virtualenvs\luffy\lib\site-packages\pymysql\connections.py", line 1075, in read
    first_packet = self.connection._read_packet()
  File "G:\virtualenvs\luffy\lib\site-packages\pymysql\connections.py", line 684, in _read_packet
    packet.check_error()
  File "G:\virtualenvs\luffy\lib\site-packages\pymysql\protocol.py", line 220, in check_error
    err.raise_mysql_exception(self._data)
  File "G:\virtualenvs\luffy\lib\site-packages\pymysql\err.py", line 109, in raise_mysql_exception
    raise errorclass(errno, errval)
pymysql.err.InternalError: (1054, "Unknown column 'fiction_author.author_gender' in 'field list'")

The above exception was the direct cause of the following exception:

Traceback (most recent call last):
  File "G:\virtualenvs\luffy\lib\site-packages\django\core\handlers\exception.py", line 35, in inner
    response = get_response(request)
  File "G:\virtualenvs\luffy\lib\site-packages\django\core\handlers\base.py", line 128, in _get_response
    response = self.process_exception_by_middleware(e, request)
  File "G:\virtualenvs\luffy\lib\site-packages\django\core\handlers\base.py", line 126, in _get_response
    response = wrapped_callback(request, *callback_args, **callback_kwargs)
  File "G:\virtualenvs\luffy\lib\site-packages\django\contrib\admin\options.py", line 575, in wrapper
    return self.admin_site.admin_view(view)(*args, **kwargs)
  File "G:\virtualenvs\luffy\lib\site-packages\django\utils\decorators.py", line 142, in _wrapped_view
    response = view_func(request, *args, **kwargs)
  File "G:\virtualenvs\luffy\lib\site-packages\django\views\decorators\cache.py", line 44, in _wrapped_view_func
    response = view_func(request, *args, **kwargs)
  File "G:\virtualenvs\luffy\lib\site-packages\django\contrib\admin\sites.py", line 223, in inner
    return view(request, *args, **kwargs)
  File "G:\virtualenvs\luffy\lib\site-packages\django\utils\decorators.py", line 62, in _wrapper
    return bound_func(*args, **kwargs)
  File "G:\virtualenvs\luffy\lib\site-packages\django\utils\decorators.py", line 142, in _wrapped_view
    response = view_func(request, *args, **kwargs)
  File "G:\virtualenvs\luffy\lib\site-packages\django\utils\decorators.py", line 58, in bound_func
    return func.__get__(self, type(self))(*args2, **kwargs2)
  File "G:\virtualenvs\luffy\lib\site-packages\django\contrib\admin\options.py", line 1708, in changelist_view
    selection_note=_('0 of %(cnt)s selected') % {'cnt': len(cl.result_list)},
  File "G:\virtualenvs\luffy\lib\site-packages\django\db\models\query.py", line 254, in __len__
    self._fetch_all()
  File "G:\virtualenvs\luffy\lib\site-packages\django\db\models\query.py", line 1179, in _fetch_all
    self._result_cache = list(self._iterable_class(self))
  File "G:\virtualenvs\luffy\lib\site-packages\django\db\models\query.py", line 53, in __iter__
    results = compiler.execute_sql(chunked_fetch=self.chunked_fetch, chunk_size=self.chunk_size)
  File "G:\virtualenvs\luffy\lib\site-packages\django\db\models\sql\compiler.py", line 1068, in execute_sql
    cursor.execute(sql, params)
  File "G:\virtualenvs\luffy\lib\site-packages\django\db\backends\utils.py", line 100, in execute
    return super().execute(sql, params)
  File "G:\virtualenvs\luffy\lib\site-packages\django\db\backends\utils.py", line 68, in execute
    return self._execute_with_wrappers(sql, params, many=False, executor=self._execute)
  File "G:\virtualenvs\luffy\lib\site-packages\django\db\backends\utils.py", line 77, in _execute_with_wrappers
    return executor(sql, params, many, context)
  File "G:\virtualenvs\luffy\lib\site-packages\django\db\backends\utils.py", line 85, in _execute
    return self.cursor.execute(sql, params)
  File "G:\virtualenvs\luffy\lib\site-packages\django\db\utils.py", line 89, in __exit__
    raise dj_exc_value.with_traceback(traceback) from exc_value
  File "G:\virtualenvs\luffy\lib\site-packages\django\db\backends\utils.py", line 85, in _execute
    return self.cursor.execute(sql, params)
  File "G:\virtualenvs\luffy\lib\site-packages\django\db\backends\mysql\base.py", line 71, in execute
    return self.cursor.execute(query, args)
  File "G:\virtualenvs\luffy\lib\site-packages\pymysql\cursors.py", line 170, in execute
    result = self._query(query)
  File "G:\virtualenvs\luffy\lib\site-packages\pymysql\cursors.py", line 328, in _query
    conn.query(q)
  File "G:\virtualenvs\luffy\lib\site-packages\pymysql\connections.py", line 517, in query
    self._affected_rows = self._read_query_result(unbuffered=unbuffered)
  File "G:\virtualenvs\luffy\lib\site-packages\pymysql\connections.py", line 732, in _read_query_result
    result.read()
  File "G:\virtualenvs\luffy\lib\site-packages\pymysql\connections.py", line 1075, in read
    first_packet = self.connection._read_packet()
  File "G:\virtualenvs\luffy\lib\site-packages\pymysql\connections.py", line 684, in _read_packet
    packet.check_error()
  File "G:\virtualenvs\luffy\lib\site-packages\pymysql\protocol.py", line 220, in check_error
    err.raise_mysql_exception(self._data)
  File "G:\virtualenvs\luffy\lib\site-packages\pymysql\err.py", line 109, in raise_mysql_exception
    raise errorclass(errno, errval)
django.db.utils.InternalError: (1054, "Unknown column 'fiction_author.author_gender' in 'field list'")
ERROR 2019-12-13 08:12:59,829 basehttp 124 "GET /admin/fiction/author/ HTTP/1.1" 500 222857
WARNING 2019-12-13 08:15:48,025 base 93 Not Found: /favicon.ico
WARNING 2019-12-13 08:15:48,025 basehttp 124 "GET /favicon.ico HTTP/1.1" 404 2084
